Workbook

Sheet rules
A1: id | B1: step | C1: next_step_open | D1: points | E1: distribution | F1: bicolor | G1: suit1 | H1: suit1_count | I1: suit2 | J1: suit2_count | K1: first_pass | L1: won_tricks | M1: def_tricks | N1: lost_tricks | O1: fit_cards | P1: stops | Q1: awake | R1: hist_bid | S1: function1 | T1: function2 | U1: arg2 | V1: function_bid | W1: arg_bid | X1: bid | Y1: symbolic_bid | Z1: artificial | AA1: forcing | AB1: convention | AC1: SEF_page | AD1: SEF_part
A2: Id | B2: Etape | C2: Prochaine étape du camp de l'ouvreur | D2: Points | E2: Distribution | F2: Bicouleurs | G2: Couleur la plus longue CL1 | H2: Cartes CL1 | I2: 2e couleur la plus longue CL2 | J2: Cartes CL2 | K2: nbr de passes avant ouverture | L2: Levées de jeu | M2: Levées de défense | N2: Perdantes max à vuln neutre | O2: Cartes de fit | P2: Nbr mini arrêts couleur(s) adverse(s) | Q2: Réveil | R2: Dernière(s) enchère(s) | S2: Spécifique 1 | T2: Spécifique 2 | V2: Calcul Enchère | X2: Enchère | Y2: Symbole enchère | Z2: Artificielle | AA2: Forcing | AB2: Convention | AC2: Page du SEF 2024 | AD2: Sous-partie du SEF
A3: 1 | B3: OPEN | D3: >=24HL | X3: 2K | Y3: 2K | Z3: 1 | AA3: manche | AB3: 2 carreau forcing de manche | AC3: 34 | AD3: Ouverture 2K
A4: 2 | B4: OPEN | D4: 17H-23HL | E4: unicolore | G4: Majeure | L4: 9 | M4: >=2 | X4: 2K | Y4: 2K | Z4: 1 | AA4: manche | AB4: 2 carreau forcing de manche | AC4: 34 | AD4: Ouverture 2K
A5: 3 | B5: OPEN | D5: 17H-23HL | E5: unicolore | G5: mineure | L5: 10 | M5: >=2 | X5: 2K | Y5: 2K | Z5: 1 | AA5: manche | AB5: 2 carreau forcing de manche | AC5: 34 | AD5: Ouverture 2K
A6: 4 | B6: OPEN | D6: 20-23HL | E6: unicolore | G6: Majeure | L6: 8.25 | M6: >=2 | X6: 2T | Y6: 2T | Z6: 1 | AA6: autoforcing | AB6: 2 fort indéterminé | AC6: 32 | AD6: Ouverture 2T
A7: 5 | B7: OPEN | D7: 20-23HL | E7: unicolore | G7: mineure | H7: >=7 | L7: 9 | X7: 2T | Y7: 2T | Z7: 1 | AA7: autoforcing | AB7: 2 fort indéterminé | AC7: 32 | AD7: Ouverture 2T
A8: 6 | B8: OPEN | D8: 21-23 HL | G8: Majeure | H8: 5 | X8: 2T | Y8: 2T | Z8: 1 | AA8: autoforcing | AB8: 2 fort indéterminé | AC8: 32 | AD8: Ouverture 2T
A9: 7 | B9: OPEN | D9: 22-23HL | E9: régulier | X9: 2T | Y9: 2T | Z9: 1 | AA9: autoforcing | AB9: 2 fort indéterminé | AC9: 32 | AD9: Ouverture 2T
A10: 8 | B10: OPEN | D10: 17H-23HL | E10: bicolore 5/5 | G10: Majeure | I10: Majeure | N10: 3 | X10: 2T | Y10: 2T | Z10: 1 | AA10: autoforcing | AB10: 2 fort indéterminé | AC10: 32 | AD10: Ouverture 2T
A11: 9 | B11: OPEN | D11: 20-21H | E11: régulier | S11: no_good_major_5 | X11: 2SA | Y11: 2SA | AC11: 35 | AD11: Ouverture 2SA
A12: 10 | B12: OPEN | C12: SEQ1SA | D12: 15H-17H | E12: régulier | S12: no_good_major_5 | X12: 1SA | Y12: 1SA | AC12: 24 | AD12: 1SA Caractéristiques
A13: 11 | B13: OPEN | C13: SEQ1SA | D13: 15-16H | E13: 5422 | G13: mineure | I13: coeur | X13: 1SA | Y13: 1SA | AC13: 24 | AD13: 1SA Caractéristiques
A14: 12 | B14: OPEN | C14: SEQ1SA | D14: 15-16H | E14: 5422 | G14: mineure | I14: carreau | X14: 1SA | Y14: 1SA | AC14: 24 | AD14: 1SA Caractéristiques
A15: 13 | B15: OPEN | C15: SEQ1SA | D15: 15-16H | E15: 6322 | G15: mineure | S15: honors_in_short_colors | X15: 1SA | Y15: 1SA | AC15: 24 | AD15: 1SA Caractéristiques
A16: 14 | B16: OPEN | C16: SEQ1SA | D16: 15-16H | E16: 5332 | S16: honors_in_short_colors | X16: 1SA | Y16: 1SA | AC16: 24 | AD16: 1SA Caractéristiques
A17: 15 | B17: OPEN | D17: 13H-23HL | E17: bicolore | G17: mineure | H17: >=6 | I17: Majeure | J17: 5 | V17: long_suit | W17: 1CL1 | Y17: 1m | AB17: Meilleure mineure | AC17: 17 | AD17: Règles ouv majeure
A18: 16 | B18: OPEN | D18: 12H-23HL | G18: Majeure | H18: >=5 | V18: long_suit | W18: 1CL1 | Y18: 1M | AB18: Majeure 5e | AC18: 17 | AD18: Règles ouv majeure
A19: 17 | B19: OPEN | D19: 12H-23HL | V19: best_minor | W19: 1 | Y19: 1m | AB19: Meilleure mineure | AC19: 11 | AD19: Règles ouv mineure
A20: 18 | B20: OPEN | D20: 12H-23HL | E20: bicolore 5/5 | F20: pique, trèfle | N20: 5 | X20: 1T | Y20: 1T | AC20: 11 | AD20: Règles ouv mineure
A21: 19 | B21: OPEN | D21: 8H-11H | G21: Majeure | H21: >=5 | K21: 2 | V21: long_suit | W21: 1CL1 | Y21: 1M | AB21: Majeure 5e | AC21: 17 | AD21: Règles ouv majeure
A22: 20 | B22: OPEN | D22: 8H11H | E22: bicolore | G22: mineure | H22: >=6 | I22: Majeure | J22: 5 | K22: 2 | V22: long_suit | W22: 1CL1 | Y22: 1m | AC22: 17 | AD22: Règles ouv majeure
A23: 21 | B23: OPEN | D23: 10H-11H | G23: pique | H23: >=5 | K23: 3 | T23: long_color_points_H | U23: >=4 | X23: 1P | Y23: 1P | AC23: 17 | AD23: Règles ouv majeure
A24: 22 | B24: OPEN | D24: 5-10H | E24: unicolore | G24: Majeure | H24: 6 | M24: <=1 | T24: long_color_points_H | U24: >=4 | V24: long_suit | W24: 2CL1 | Y24: 2M | AB24: Barrage | AC24: 29 | AD24: 2M faible Caract
A25: 23 | B25: OPEN | D25: 5-10H | E25: unicolore | H25: 7 | T25: long_color_points_H | U25: >=4 | V25: long_suit | W25: 3CL1 | Y25: 3E | AB25: Barrage | AC25: 30 | AD25: Barrage 3 Caract
A26: 24 | B26: OPEN | D26: 5-10H | E26: unicolore | H26: 8 | T26: long_color_points_H | U26: >=4 | V26: long_suit | W26: 4CL1 | Y26: 4E | AB26: Barrage | AC26: 30 | AD26: Barrage 4 Caract
A27: 25 | B27: OPEN | D27: 10-16H | E27: unicolore | G27: mineure | H27: >=7 | T27: long_color_points_H | U27: 10 | X27: 3SA | Y27: 3SA | AB27: Mineure affranchie | AC27: 31 | AD27: 3SA Caract
A28: 26 | B28: ROSA | D28: 5-10H | E28: irrégulier | K28: >=2 | O28: 4 | R28: 1M - | V28: support | W28: 3 | Y28: 3M | AB28: Barrage | AC28: 19 | AD28: ROSAAP soutien
A29: 27 | B29: ROSA | D29: >=11HLD | K29: >=2 | O29: 4 | R29: 1M - | S29: any_short_color | X29: 2SA | Y29: 2SA | AC29: 19 | AD29: ROSAAP soutien
A30: 28 | B30: ROSA | D30: >=11HLD | K30: >=2 | O30: 3 | R30: 1M - | S30: any_short_color | X30: 2T | Y30: 2T | Z30: 1 | AA30: forcing | AB30: Drury | AC30: 20 | AD30: ROSAAP soutien
A31: 29 | B31: ROSA | D31: >=11HLD | K31: >=2 | O31: >=4 | R31: 1M - | X31: 2T | Y31: 2T | Z31: 1 | AA31: forcing | AB31: Drury | AC31: 20 | AD31: ROSAAP soutien
A32: 30 | B32: ROSA | D32: 8-10H | K32: >=2 | O32: <3 | R32: 1C - | T32: suit_length | U32: P>=4 | X32: 1P | Y32: 1P | AC32: 20 | AD32: ROSAAP chang couleur
A33: 31 | B33: ROSA | D33: 8-10H | H33: >=6 | K33: >=2 | O33: <3 | R33: 1M - | V33: long_suit | W33: 2CL1 | Y33: 2E | AC33: 20 | AD33: ROSAAP chang couleur
A34: 32 | B34: ROSA | D34: 8-10H | H34: 5 | K34: >=2 | O34: <3 | R34: 1M - | T34: long_color_points_H | U34: >=7 | V34: long_suit | W34: 2CL1 | Y34: 2E | AC34: 20 | AD34: ROSAAP chang couleur
A35: 33 | B35: ROSA | D35: 8-11H | H35: >=5 | K35: >=2 | O35: >=4 | R35: 1C - | T35: long_color_points_H | U35: >=5 | X35: 2P | Y35: 2P | AB35: Enchère de rencontre | AC35: 20 | AD35: ROSAAP chang couleur
A36: 34 | B36: ROSA | D36: 8-11H | H36: >=5 | K36: >=2 | O36: >=4 | R36: 1M - | T36: long_color_points_H | U36: >=5 | V36: long_suit | W36: 3CL1 | Y36: 3E | AB36: Enchère de rencontre | AC36: 20 | AD36: ROSAAP chang couleur
A37: 35 | B37: ROSA | D37: 6-11H | K37: >=2 | O37: <3 | R37: 1M - | X37: 1SA | Y37: 1SA | AC37: 20 | AD37: ROSAAP 1SA
A38: 36 | B38: ROSA | D38: 6-10HLD | O38: >=3 | R38: 1M - | V38: support | W38: 2 | Y38: 2M | AC38: 17 | AD38: ROSA
A39: 37 | B39: ROSA | D39: 11-12HLD | O39: 3 | R39: 1M - | X39: 2SA | Y39: 2SA | Z39: 1 | AA39: forcing | AB39: 2 SA fitté | AC39: 17 | AD39: ROSA
A40: 38 | B40: ROSA | D40: 11-12HLD | O40: 4 | R40: 1M - | V40: support | W40: 3 | Y40: 3M | AC40: 17 | AD40: ROSA
...

Sheet columns
A1: Colonne | B1: Concerne | C1: Description | D1: Format | E1: Enumération | F1: Valeurs
A2: Id | C2: Entier qui doit être unique | D2: int
A3: Variante | B3: Système d'enchère | C3: Variante par rapport au SEF pour certaines règles | D3: string | E3: oui
A4: Remplace la règle SEF | B4: Système d'enchère | C4: Numéro de la règle SEF que la variante remplace | D4: int
A5: Etape | B5: Joueur courant | C5: Etape des enchères dans laquelle se trouve le joueur | E5: oui
A6: Séquence | B6: Enchainement des enchères | C6: Doit appartenir à la séquence en cours si l'étape obéit à une séquence | D6: string | E6: oui
A7: Points | B7: Main du joueur courant | C7: Condition sur les points du joueur | D7: [OP]nnn[H][L][-nnn]H[L][D] | F7: OP deux valeurs possibles: <= ou >=
A8: Distribution | B8: Main du joueur courant | C8: Distribution de la main | D8: string en minuscule ou entier à 4 chiffres | E8: oui
A9: Bicouleurs | B9: Main du joueur courant | C9: 2 Couleurs du bicolore (ordre indifférent) | D9: strings en minuscule séparés par ' ,' | E9: oui | F9: les 4 couleurs
A10: Couleur la plus longue CL1 | B10: Main du joueur courant | D10: string en minuscule | E10: oui | F10: une des 4 couleurs ou majeure ou mineure
A11: cartes de CL1 | B11: Main du joueur courant | C11: Nombre de cartes dans la couleur CL1 | D11: [>=]nnn
A12: 2e couleur la plus longue CL2 | B12: Main du joueur courant | D12: string en minuscule | E12: oui | F12: une des 4 couleurs ou majeure ou mineure
A13: Cartes CL2 | B13: Main du joueur courant | C13: Nombre de cartes dans la couleur CL2 | D13: [>=]nnn
A14: Nbr de passes avant ouverture | B14: Joueur courant | D14: Opn
A15: Levées de jeu | B15: Main du joueur courant | C15: Nombre mini requis de levées de jeu | D15: float
A16: Levées de défense | B16: Main du joueur courant | C16: Nombre de levées de défense | D16: [>=][<=]nnn
A17: Perdantes | B17: Main du joueur courant | C17: Nombre max de perdantes à vulnérabilités équivalentes | D17: n ou (a,b,c) | F17: ajouter 1 si vuln favorable et -1 si défavorable
A18: Cartes de fit | B18: Main du joueur courant | C18: Cartes dans la couleur du partenaire | D18: OPnnn
A19: Nbr mini arrêts couleur adverse | B19: Main du joueur courant | C19: Nombre minimum d'arrêts dans la couleur adverse | D19: int
A20: Réveil | B20: Historique des enchères
A21: Enchère antérieure | B21: Historique des enchères | D21: BIDab='enchère'
A22: Dernière(s) enchère(s) | B22: Historique des enchères | C22: Une ou plusieurs enchères consécutives juste avant le joueur courant | D22: ench ench ench… | E22: non | F22: Cf Symboles des enchères ci-dessous
A23: Spécifique 1 | B23: Main du joueur courant | C23: Fonction à appeler | D23: string
A24: arg1 | C24: Paramètre à transmettre pour appel de la fonction 1 | D24: string
A25: Spécifique 2 | B25: Main et/ou historique enchères | C25: Fonction à appeler | D25: string
A26: Spécifique 3 | B26: Main et/ou historique enchères | C26: Fonction à appeler | D26: string
A27: Calcul Enchère | B27: Enchère, et pas une condition | C27: Fonction à appeler | D27: string
A28: arg_bid | B28: Enchère, et pas une condition | C28: Paramètre à transmettre pour appel de la fonction Calcul enchère | D28: string
A29: Enchère | B29: Enchère, et pas une condition | C29: Enchère exacte à déclarer | D29: string
A30: Symbole enchère | B30: Enchère, et pas une condition | C30: Représentation symbolique de l'enchère | D30: string
A31: Artificielle | B31: Enchère, et pas une condition | D31: 1 ou vide | F31: 1 si enchère artificielle
A32: Forcing | B32: Enchère, et pas une condition | D32: string | E32: enum
A33: Convention | B33: Enchère, et pas une condition | C33: Dénomination de la convention | D33: string
A34: Page du SEF | C34: Indicatif, pas utile pour le moteur
A35: Sous-partie du SEF | C35: Indicatif, pas utile pour le moteur
A38: Format
A39: [x] | B39: x facultatif
A40: nnn ou ppp | B40: entiers
A41: OP | B41: <, <=, >=, >, vide (signifie =)
A44: Situations
...

Sheet help
A1: DEFINITIONS
A2: Le joueur courant est celui dont c'est le tour d'enchérir.
A3: Une règle correspond à une ligne de l'onglet règles. Une règle est composée de plusieurs conditions.
A4: Une condition correspond à une case de l'onglet règles.
A5: Toutes les conditions de la ligne doivent être satisfaites pour que la règle soit satisfaite.
A8: LECTURE DES CONDITIONS
A9: Filtrer sur la situation du joueur courant.
A10: Sans indication contraire, les règles s'appliquent sur la main du joueur courant.
A11: Les règles s'analysent une par une de haut en bas.
A12: Dès qu'une règle est satisfaite, l'enchère correspondante est énoncée par le joueur courant, et arrêt.
A13: L'enchère est PASSE si aucune règle n'est satisfaite pour la situation et le système donnés.
A16: CONDITIONS IMPLICITES
... A22: La 2e ligne est un titre en français

Sheet SEF
A1: Exhaustivité des règles / SEF 2024
A3: Chapitre | B3: page | C3: couverture page | E3: Intitulé chapitre | F3: Partie | G3: couverture partie | H3: non couvert dans la page
A4: 2 | B4: 11 | C4: 1 | E4: Ouvertures mineures | F4: Ouverture et ROSA | G4: 1
A5: 2 | B5: 12 | C5: 1 | E5: Ouvertures mineures | F5: ROSA | G5: 1
A6: 2 | B6: 13 | C6: 1 | E6: Ouvertures mineures | F6: ROACA et ROAIC | G6: 1
A7: 2 | B7: 14 | C7: 0.5 | E7: Ouvertures mineures | F7: ROAIC | G7: 1 | H7: Séquence 1K 2T X
A8: 2 | B8: 15 | C8: 1 | E8: Ouvertures mineures | F8: ROAIC et ROAI1SA | G8: 1
A9: 2 | B9: 16 | C9: 0 | E9: Ouvertures mineures | F9: ROAIBI | G9: 0 | H9: Rép après interv bicolore et rép au contre Spoutnik simple
A10: 3 | B10: 17 | C10: 1 | E10: Ouvertures majeures | F10: Ouverture et ROSA | G10: 1
A11: 3 | B11: 18 | C11: 0.9 | E11: Ouvertures majeures | F11: ROSA | G11: 1 | H11: Avec au moins 16HLD changer puis soutenir au palier 3
A12: 3 | B12: 19 | C12: 0.6 | E12: Ouvertures majeures | F12: ROSA | G12: 1
A13: 3 | B13: 20 | C13: 0.7 | E13: Ouvertures majeures | F13: ROSA et RAOACA | G13: 1 | H13: dév suite rép 2SA, et réponses au Drury
A14: 3 | B14: 21 | C14: 1 | E14: Ouvertures majeures | F14: ROACA et ROAIC | G14: 1
A15: 3 | B15: 22 | C15: 1 | E15: Ouvertures majeures | F15: ROAIC et ROAI1SA | G15: 1
A16: 3 | B16: 23 | C16: 0 | E16: Ouvertures majeures | F16: ROAIBI | G16: 0 | H16: Rép après interv bicolore
A17: 4 | B17: 24 | C17: 1 | E17: Ouverture de 1SA | F17: Ouverture et réponses à SA | G17: 1
A18: 4 | B18: 25 | C18: 1 | E18: Ouverture de 1SA | F18: Stayman | G18: 1
A19: 4 | B19: 26 | C19: 1 | E19: Ouverture de 1SA | F19: Texas | G19: 1
A20: 4 | B20: 27 | C20: 0.1 | E20: Ouverture de 1SA | F20: Texas et saut coul et Rubensohl | G20: 0
A21: 4 | B21: 28 | E21: Ouverture de 1SA | F21: Après intervention du n°4
A22: 5 | B22: 29 | C22: 0.6 | E22: Ouvertures de barrage | F22: Ouverture seule | G22: 1
A23: 5 | B23: 30 | C23: 0.2 | E23: Ouvertures de barrage | F23: Ouverture seule | G23: 1
A24: 5 | B24: 31 | C24: 0.2 | E24: Ouvertures de barrage | F24: Ouverture seule | G24: 1
A25: 6 | B25: 32 | C25: 0.4 | E25: Ouvertures fortes | F25: Ouverture seule | G25: 1
A26: 6 | B26: 34 | C26: 0.4 | E26: Ouvertures fortes | F26: Ouverture seule | G26: 1
A27: 6 | B27: 35 | C27: 0.2 | E27: Ouvertures fortes | F27: Ouverture seule | G27: 1
A28: 10 | B28: 66 | C28: 1 | E28: Interventions et réveils | F28: Interv du n°2
A29: 10 | B29: 67 | C29: 1 | E29: Interventions et réveils | F29: Interv du n°2
A30: 10 | B30: 68 | C30: 1 | E30: Interventions et réveils | F30: Interv du n°4
A31: 10 | B31: 69 | C31: 0.7 | E31: Interventions et réveils | F31: Interv du n°4 | G31: 1 | H31: Rép aux interventions

Sheet conclude
A1: Finalisation des enchères
A2: id | B2: step | C2: hist_bid | D2: artificial | E2: forcing | F2: convention | G2: comment
A3: 305 | B3: =VLOOKUP($A3,rules!$A:$Y,2,FALSE) -> STAYMAN | C3: =VLOOKUP($A3,rules!$A:$Y,18,FALSE) & " " & VLOOKUP($A3,rules!$A:$Y,25,FALSE) -> 2T - 2K - 3m | D3: =VLOOKUP($A3,rules!$A:$AB,26,FALSE) -> 0 | E3: =VLOOKUP($A3,rules!$A:$AB,27,FALSE) -> manche | F3: =VLOOKUP($A3,rules!$A:$AB,28,FALSE) -> Stayman
A4: 306 | B4: =VLOOKUP($A4,rules!$A:$Y,2,FALSE) -> STAYMAN | C4: =VLOOKUP($A4,rules!$A:$Y,18,FALSE) & " " & VLOOKUP($A4,rules!$A:$Y,25,FALSE) -> 2T - 2K - 3m | D4: =VLOOKUP($A4,rules!$A:$AB,26,FALSE) -> 0 | E4: =VLOOKUP($A4,rules!$A:$AB,27,FALSE) -> manche | F4: =VLOOKUP($A4,rules!$A:$AB,28,FALSE) -> Stayman
A5: 317 | B5: =VLOOKUP($A5,rules!$A:$Y,2,FALSE) -> STAYMAN | C5: =VLOOKUP($A5,rules!$A:$Y,18,FALSE) & " " & VLOOKUP($A5,rules!$A:$Y,25,FALSE) -> 2T - 2C - 3P | D5: =VLOOKUP($A5,rules!$A:$AB,26,FALSE) -> 1 | E5: =VLOOKUP($A5,rules!$A:$AB,27,FALSE) -> forcing | F5: =VLOOKUP($A5,rules!$A:$AB,28,FALSE) -> Convention 2012 | G5: ambition de chelem
A6: 318 | B6: =VLOOKUP($A6,rules!$A:$Y,2,FALSE) -> STAYMAN | C6: =VLOOKUP($A6,rules!$A:$Y,18,FALSE) & " " & VLOOKUP($A6,rules!$A:$Y,25,FALSE) -> 2T - 2P - 3C | D6: =VLOOKUP($A6,rules!$A:$AB,26,FALSE) -> 1 | E6: =VLOOKUP($A6,rules!$A:$AB,27,FALSE) -> forcing | F6: =VLOOKUP($A6,rules!$A:$AB,28,FALSE) -> Convention 2012 | G6: ambition de chelem
A7: 319 | B7: =VLOOKUP($A7,rules!$A:$Y,2,FALSE) -> STAYMAN | C7: =VLOOKUP($A7,rules!$A:$Y,18,FALSE) & " " & VLOOKUP($A7,rules!$A:$Y,25,FALSE) -> 2T - 2M - 3m | D7: =VLOOKUP($A7,rules!$A:$AB,26,FALSE) -> 0 | E7: =VLOOKUP($A7,rules!$A:$AB,27,FALSE) -> manche | F7: =VLOOKUP($A7,rules!$A:$AB,28,FALSE) -> Stayman
A8: 320 | B8: =VLOOKUP($A8,rules!$A:$Y,2,FALSE) -> STAYMAN | C8: =VLOOKUP($A8,rules!$A:$Y,18,FALSE) & " " & VLOOKUP($A8,rules!$A:$Y,25,FALSE) -> 2T - 2M - 3m | D8: =VLOOKUP($A8,rules!$A:$AB,26,FALSE) -> 0 | E8: =VLOOKUP($A8,rules!$A:$AB,27,FALSE) -> manche | F8: =VLOOKUP($A8,rules!$A:$AB,28,FALSE) -> Stayman
A9: 325 | B9: =VLOOKUP($A9,rules!$A:$Y,2,FALSE) -> STAYMAN | C9: =VLOOKUP($A9,rules!$A:$Y,18,FALSE) & " " & VLOOKUP($A9,rules!$A:$Y,25,FALSE) -> 2T - 2SA - 3C | D9: =VLOOKUP($A9,rules!$A:$AB,26,FALSE) -> 0 | E9: =VLOOKUP($A9,rules!$A:$AB,27,FALSE) -> forcing | F9: =VLOOKUP($A9,rules!$A:$AB,28,FALSE) -> 0 | G9: ambition de chelem
A10: 326 | B10: =VLOOKUP($A10,rules!$A:$Y,2,FALSE) -> STAYMAN | C10: =VLOOKUP($A10,rules!$A:$Y,18,FALSE) & " " & VLOOKUP($A10,rules!$A:$Y,25,FALSE) -> 2T - 2SA - 3P | D10: =VLOOKUP($A10,rules!$A:$AB,26,FALSE) -> 0 | E10: =VLOOKUP($A10,rules!$A:$AB,27,FALSE) -> forcing | F10: =VLOOKUP($A10,rules!$A:$AB,28,FALSE) -> 0 | G10: ambition de chelem
A11: 327 | B11: =VLOOKUP($A11,rules!$A:$Y,2,FALSE) -> STAYMAN | C11: =VLOOKUP($A11,rules!$A:$Y,18,FALSE) & " " & VLOOKUP($A11,rules!$A:$Y,25,FALSE) -> 2T - 2M - 4T | D11: =VLOOKUP($A11,rules!$A:$AB,26,FALSE) -> 1 | E11: =VLOOKUP($A11,rules!$A:$AB,27,FALSE) -> 0 | F11: =VLOOKUP($A11,rules!$A:$AB,28,FALSE) -> Splinter
A12: 328 | B12: =VLOOKUP($A12,rules!$A:$Y,2,FALSE) -> STAYMAN | C12: =VLOOKUP($A12,rules!$A:$Y,18,FALSE) & " " & VLOOKUP($A12,rules!$A:$Y,25,FALSE) -> 2T - 2M - 4K | D12: =VLOOKUP($A12,rules!$A:$AB,26,FALSE) -> 1 | E12: =VLOOKUP($A12,rules!$A:$AB,27,FALSE) -> 0 | F12: =VLOOKUP($A12,rules!$A:$AB,28,FALSE) -> Splinter
A13: 329 | B13: =VLOOKUP($A13,rules!$A:$Y,2,FALSE) -> STAYMAN | C13: =VLOOKUP($A13,rules!$A:$Y,18,FALSE) & " " & VLOOKUP($A13,rules!$A:$Y,25,FALSE) -> 2T - 2P - 4C | D13: =VLOOKUP($A13,rules!$A:$AB,26,FALSE) -> 1 | E13: =VLOOKUP($A13,rules!$A:$AB,27,FALSE) -> 0 | F13: =VLOOKUP($A13,rules!$A:$AB,28,FALSE) -> Splinter

Sheet tree
B1: BID11 | D1: BID12 | F1: BID13
A3: 1 à 3 | B3: 2K
A7: 4 à 8 | B7: 2T
A11: la 9 | B11: 2SA
A17: 10 à 14 | B17: 1SA | D17: PASSE
A26: 15, 16 et 19 | B26: 1M | D26: PASSE | E26: 35 et 50 | F26: 1SA
B27: (1C) | E27: 30 et 49 | F27: 1P
E28: 31 et 32 | F28: 2E
E29: la 48 | F29: 2m
E30: 28, 29 et 40 | F30: 2T
E31: la 39 | F31: 2K
E32: la 36 | F32: 2M
B33: (1P) | E33: la 47 | F33: 2C
B34: (1C) | E34: la 33 | F34: 2P
E35: 31, 32 | F35: 2E
E36: 27 et 37 | F36: 2SA
E37: la 46 | F37: 3P
E38: 26 et 38 | F38: 3M
E39: la 34 | F39: 3E
E40: la 41 | F40: 3SA
E41: la 43 | F41: 4T
E42: la 44 | F42: 4K
E43: la 45 | F43: 4C
E44: la 42 | F44: 4M
A47: la 21 | B47: 1P | C47: Cf 1M
A52: 17 ou 20 | B52: 1m
D53: 1M
D54: 2M
D55: 3E
D56: 4E
D57: 1SA
D58: 2SA
D59: 3SA
D60: 2m
D61: 3m
A65: la 18 | B65: 1T
D66: 1K
D67: 2K
D68: 5K
A72: aucune | B72: 1K
...
